<?xml version="1.0" ?>
<robot name="stance_r_gravity" xmlns:xacro="http://www.ros.org/wiki/xacro">

<xacro:include filename="$(find stance_r_gravity_description)/urdf/materials.xacro" />
<xacro:include filename="$(find stance_r_gravity_description)/urdf/stance_r_gravity.trans" />
<xacro:include filename="$(find stance_r_gravity_description)/urdf/stance_r_gravity.gazebo" />
<link name="base_link">
  <inertial>
    <origin xyz="-0.007193439718706408 -0.09999996456328823 0.003977742782351984" rpy="0 0 0"/>
    <mass value="0.11348144787449325"/>
    <inertia ixx="6.4e-05" iyy="0.000197" izz="0.000255" ixy="-0.0" iyz="-0.0" ixz="4e-06"/>
  </inertial>
  <visual>
    <origin xyz="0 0 0" rpy="0 0 0"/>
    <geometry>
      <mesh filename="file://$(find stance_r_gravity_description)/meshes/base_link.stl" scale="0.001 0.001 0.001"/>
    </geometry>
    <material name="silver"/>
  </visual>
  <collision>
    <origin xyz="0 0 0" rpy="0 0 0"/>
    <geometry>
      <mesh filename="file://$(find stance_r_gravity_description)/meshes/base_link.stl" scale="0.001 0.001 0.001"/>
    </geometry>
  </collision>
</link>

<link name="B_UNCA10_ros_v4_1">
  <inertial>
    <origin xyz="-6.766447069317636e-14 -4.163336342344337e-17 1.8041124150158794e-16" rpy="0 0 0"/>
    <mass value="0.0048216566019272334"/>
    <inertia ixx="0.0" iyy="0.0" izz="0.0" ixy="0.0" iyz="0.0" ixz="0.0"/>
  </inertial>
  <visual>
    <origin xyz="0.0 0.1 -0.026" rpy="0 0 0"/>
    <geometry>
      <mesh filename="file://$(find stance_r_gravity_description)/meshes/B_UNCA10_ros_v4_1.stl" scale="0.001 0.001 0.001"/>
    </geometry>
    <material name="silver"/>
  </visual>
  <collision>
    <origin xyz="0.0 0.1 -0.026" rpy="0 0 0"/>
    <geometry>
      <mesh filename="file://$(find stance_r_gravity_description)/meshes/B_UNCA10_ros_v4_1.stl" scale="0.001 0.001 0.001"/>
    </geometry>
  </collision>
</link>

<link name="shank_ros_v5_1">
  <inertial>
    <origin xyz="0.004984925329671789 7.259530372741296e-06 0.19309035594407767" rpy="0 0 0"/>
    <mass value="0.17890207652074486"/>
    <inertia ixx="0.001648" iyy="0.001636" izz="6.4e-05" ixy="0.0" iyz="0.0" ixz="-6.5e-05"/>
  </inertial>
  <visual>
    <origin xyz="-0.0 0.1 -0.026" rpy="0 0 0"/>
    <geometry>
      <mesh filename="file://$(find stance_r_gravity_description)/meshes/shank_ros_v5_1.stl" scale="0.001 0.001 0.001"/>
    </geometry>
    <material name="silver"/>
  </visual>
  <collision>
    <origin xyz="-0.0 0.1 -0.026" rpy="0 0 0"/>
    <geometry>
      <mesh filename="file://$(find stance_r_gravity_description)/meshes/shank_ros_v5_1.stl" scale="0.001 0.001 0.001"/>
    </geometry>
  </collision>
</link>

<link name="Thigh_R_v3_1">
  <inertial>
    <origin xyz="0.0016457802203221116 0.005746453261716689 0.16334952544392162" rpy="0 0 0"/>
    <mass value="2.3812347441494124"/>
    <inertia ixx="0.012971" iyy="0.010328" izz="0.005628" ixy="2e-06" iyz="-0.000581" ixz="0.00031"/>
  </inertial>
  <visual>
    <origin xyz="-0.0 0.1 -0.2815" rpy="0 0 0"/>
    <geometry>
      <mesh filename="file://$(find stance_r_gravity_description)/meshes/Thigh_R_v3_1.stl" scale="0.001 0.001 0.001"/>
    </geometry>
    <material name="silver"/>
  </visual>
  <collision>
    <origin xyz="-0.0 0.1 -0.2815" rpy="0 0 0"/>
    <geometry>
      <mesh filename="file://$(find stance_r_gravity_description)/meshes/Thigh_R_v3_1.stl" scale="0.001 0.001 0.001"/>
    </geometry>
  </collision>
</link>

<link name="r_hip_pitch_ros_v2_1">
  <inertial>
    <origin xyz="1.4334111525204064e-14 0.029750787350574806 0.022749999529228848" rpy="0 0 0"/>
    <mass value="0.09452024478783433"/>
    <inertia ixx="0.000169" iyy="0.000138" izz="0.000134" ixy="-0.0" iyz="-5e-06" ixz="-0.0"/>
  </inertial>
  <visual>
    <origin xyz="-0.0 0.081 -0.5015" rpy="0 0 0"/>
    <geometry>
      <mesh filename="file://$(find stance_r_gravity_description)/meshes/r_hip_pitch_ros_v2_1.stl" scale="0.001 0.001 0.001"/>
    </geometry>
    <material name="silver"/>
  </visual>
  <collision>
    <origin xyz="-0.0 0.081 -0.5015" rpy="0 0 0"/>
    <geometry>
      <mesh filename="file://$(find stance_r_gravity_description)/meshes/r_hip_pitch_ros_v2_1.stl" scale="0.001 0.001 0.001"/>
    </geometry>
  </collision>
</link>

<link name="hip_yaw_ros_v3_1">
  <inertial>
    <origin xyz="-0.015686028210591632 1.0747219273056496e-05 0.0404784703527421" rpy="0 0 0"/>
    <mass value="1.3123446705318125"/>
    <inertia ixx="0.000955" iyy="0.002546" izz="0.002645" ixy="0.0" iyz="0.0" ixz="1.2e-05"/>
  </inertial>
  <visual>
    <origin xyz="-0.0 0.049 -0.5565" rpy="0 0 0"/>
    <geometry>
      <mesh filename="file://$(find stance_r_gravity_description)/meshes/hip_yaw_ros_v3_1.stl" scale="0.001 0.001 0.001"/>
    </geometry>
    <material name="silver"/>
  </visual>
  <collision>
    <origin xyz="-0.0 0.049 -0.5565" rpy="0 0 0"/>
    <geometry>
      <mesh filename="file://$(find stance_r_gravity_description)/meshes/hip_yaw_ros_v3_1.stl" scale="0.001 0.001 0.001"/>
    </geometry>
  </collision>
</link>

<link name="waist_ros_v2_1">
  <inertial>
    <origin xyz="0.004448787386114094 0.04899999999974363 0.03125357113276561" rpy="0 0 0"/>
    <mass value="0.1903032786352579"/>
    <inertia ixx="0.00052" iyy="0.000694" izz="0.000957" ixy="-0.0" iyz="0.0" ixz="5.3e-05"/>
  </inertial>
  <visual>
    <origin xyz="0.007 0.049 -0.598" rpy="0 0 0"/>
    <geometry>
      <mesh filename="file://$(find stance_r_gravity_description)/meshes/waist_ros_v2_1.stl" scale="0.001 0.001 0.001"/>
    </geometry>
    <material name="silver"/>
  </visual>
  <collision>
    <origin xyz="0.007 0.049 -0.598" rpy="0 0 0"/>
    <geometry>
      <mesh filename="file://$(find stance_r_gravity_description)/meshes/waist_ros_v2_1.stl" scale="0.001 0.001 0.001"/>
    </geometry>
  </collision>
</link>

<joint name="R_Ankle_Roll" type="revolute">
  <origin xyz="0.0 -0.1 0.026" rpy="0 0 0"/>
  <parent link="base_link"/>
  <child link="B_UNCA10_ros_v4_1"/>
  <axis xyz="1.0 0.0 -0.0"/>
  <limit upper="0.436332" lower="-0.436332" effort="100" velocity="100"/>
</joint>

<joint name="R_Ankle_Pitch" type="revolute">
  <origin xyz="0.0 0.0 0.0" rpy="0 0 0"/>
  <parent link="B_UNCA10_ros_v4_1"/>
  <child link="shank_ros_v5_1"/>
  <axis xyz="-0.0 1.0 -0.0"/>
  <limit upper="0.436332" lower="-0.436332" effort="100" velocity="100"/>
</joint>

<joint name="R_Knee_Pitch" type="revolute">
  <origin xyz="0.0 0.0 0.2555" rpy="0 0 0"/>
  <parent link="shank_ros_v5_1"/>
  <child link="Thigh_R_v3_1"/>
  <axis xyz="0.0 1.0 0.0"/>
  <limit upper="0.0" lower="-1.919862" effort="100" velocity="100"/>
</joint>

<joint name="R_Hip_Pitch" type="revolute">
  <origin xyz="0.0 0.019 0.22" rpy="0 0 0"/>
  <parent link="Thigh_R_v3_1"/>
  <child link="r_hip_pitch_ros_v2_1"/>
  <axis xyz="0.0 1.0 0.0"/>
  <limit upper="1.570796" lower="-1.570796" effort="100" velocity="100"/>
</joint>

<joint name="R_Hip_Yaw" type="revolute">
  <origin xyz="0.0 0.032 0.055" rpy="0 0 0"/>
  <parent link="r_hip_pitch_ros_v2_1"/>
  <child link="hip_yaw_ros_v3_1"/>
  <axis xyz="0.0 0.0 1.0"/>
  <limit upper="0.523599" lower="-0.523599" effort="100" velocity="100"/>
</joint>

<joint name="R_Hip_Roll" type="revolute">
  <origin xyz="-0.007 0.0 0.0415" rpy="0 0 0"/>
  <parent link="hip_yaw_ros_v3_1"/>
  <child link="waist_ros_v2_1"/>
  <axis xyz="1.0 -0.0 0.0"/>
  <limit upper="0.523599" lower="-0.523599" effort="100" velocity="100"/>
</joint>

</robot>
